Workbook
Name \0: #N/A
Name \a: #N/A
Name \b: #N/A
Name \c: #N/A
Name \CO: #REF!
Name \COGS: #REF!
Name \d: #N/A
Name \DS: #REF!
Name \e: #N/A
Name \ED: #REF!
Name \F: #REF!
Name \g: #N/A
Name \GA: #REF!
Name \H: #REF!
Name \I: #REF!
Name \j: #REF!
Name \k: #REF!
Name \l: #REF!
Name \M: #REF!
Name \n: #N/A
Name \o: #N/A
Name \p: #N/A
Name \PR: #REF!
Name \PS: #REF!
Name \q: #N/A
Name \r: #REF!
Name \s: #REF!
Name \t: #N/A
Name \U: #REF!
Name \W: #REF!
Name \WH: #REF!
Name \X: #REF!
Name \y: #N/A
Name \z: #REF!
Name ____________________________________NPW1: #REF!
Name ____________________________________NPW10: #REF!
Name ____________________________________NPW11: #REF!
Name ____________________________________NPW2: #REF!
Name ____________________________________NPW3: #REF!
Name ____________________________________NPW4: #REF!
Name ____________________________________NPW5: #REF!
Name ____________________________________NPW6: #REF!
Name ____________________________________NPW7: #REF!
Name ____________________________________NPW8: #REF!
Name ____________________________________NPW9: #REF!
Name ___________________________________NPW1: #REF!
Name ___________________________________NPW10: #REF!
Name ___________________________________NPW11: #REF!
Name ___________________________________NPW2: #REF!
Name ___________________________________NPW3: #REF!
Name ___________________________________NPW4: #REF!
Name ___________________________________NPW5: #REF!
Name ___________________________________NPW6: #REF!
Name ___________________________________NPW7: #REF!
Name ___________________________________NPW8: #REF!
Name ___________________________________NPW9: #REF!
Name __________________________________NPW1: #REF!
Name __________________________________NPW10: #REF!
Name __________________________________NPW11: #REF!
Name __________________________________NPW2: #REF!

Sheet Daily Sales Performance
A1: PT CKD OTTO PHARMACEUTICALS EXECUTIVE INFORMATION SUMMARY | I1: DAILY SALES PERFORMANCE | P1: 2025
P3: December
AB4: 
A5: As of | F5: Bussiness Plan | K5: Expectation Closing | P5: Achievment
N6: (in Million IDR)
A7: 46022 | F7: {=_xlfn.IFS(P3="January",Apendix!G77,P3="February",Apendix!H77,P3="march",Apendix!I77,P3="April",Apendix!J77,P3="May",Apendix!K77,P3="June",Apendix!L77,P3="July",Apendix!M77,P3="August",Apendix!N77,P3="September",Apendix!O77,P3="October",Apendix!P77,P3="November",Apendix!Q77,P3="December",Apendix!R77)} -> 6605.5799 | K7: {=_xlfn.IFS(P3="January",Apendix!G78,P3="February",Apendix!H78,P3="march",Apendix!I78,P3="April",Apendix!J78,P3="May",Apendix!K78,P3="June",Apendix!L78,P3="July",Apendix!M78,P3="August",Apendix!N78,P3="September",Apendix!O78,P3="October",Apendix!P78,P3="November",Apendix!Q78,P3="December",Apendix!R78)} -> 5347.7821 | P7: =+K7/F7 -> 0.80958556
A9: Achievement

Sheet >>

Sheet Apendix
A1: PT CKD OTTO PHARMACEUTICALS Daily Sales
C7: January | D7: February | E7: March | F7: April | G7: May | H7: June | I7: July | J7: August | K7: September | L7: October | M7: November | N7: December | O7: Total
B8: Business Plan | C8: 5840.8361 | D8: 6384.4032 | E8: 6581.2264 | F8: 6839.8032 | G8: 6597.9355 | H8: 6706.5427 | I8: 7295.3604 | J8: 7569.093 | K8: 7763.1358 | L8: 8374.9526 | M8: 8441.1287 | N8: 6605.5799 | O8: =SUM(C8:N8) -> 84999.998
B9: AVG | C9: =+C8 -> 5840.8361 | D9: =AVERAGE($B8:D8) -> 6112.6197 | E9: =AVERAGE($B8:E8) -> 6268.8219 | F9: =AVERAGE($B8:F8) -> 6411.5672 | G9: =AVERAGE($B8:G8) -> 6448.8409 | H9: =AVERAGE($B8:H8) -> 6491.7912 | I9: =AVERAGE($B8:I8) -> 6606.5868 | J9: =AVERAGE($B8:J8) -> 6726.9001 | K9: =AVERAGE($B8:K8) -> 6842.0374 | ... N9: =AVERAGE($B8:N8) -> 7083.3331 | O9: =AVERAGE($B8:N8) -> 7083.3331
B10: Estimation | C10: =SUM(C14:C40) -> 7165.1067 | D10: =SUM(D14:D40) -> 6072.4376 | E10: =SUM(E14:E40) -> 6047.7187 | F10: =SUM(F14:F40) -> 5877.2441 | G10: =SUM(G14:G40) -> 6745.9862 | H10: =SUM(H14:H40) -> 6104.9563 | I10: =SUM(I14:I40) -> 7897.0778 | J10: =SUM(J14:J40) -> 6645.1764 | ... M10: =SUM(M14:M40) -> 9447.5324 | N10: =SUM(N14:N30) -> 3558.2556 | O10: =SUM(C10:N10) -> 80661.393
B11: Ach | C11: =+C10/C8 -> 1.2267262 | D11: =+D10/D8 -> 0.95113628 | E11: =+E10/E8 -> 0.91893492 | F11: =+F10/F8 -> 0.85927094 | G11: =+G10/G8 -> 1.0224389 | H11: =+H10/H8 -> 0.91029858 | I11: =+I10/I8 -> 1.0824795 | J11: =+J10/J8 -> 0.87793562 | ... N11: =+N10/N8 -> 0.53867422 | S11: h
B13: WD | C13: January | D13: February | E13: March | F13: April | G13: May | H13: June | I13: July | J13: August | K13: September | L13: October | M13: November | N13: December | O13: Total | P13: Average | Q13: % achiev
B14: 1 | C14: 143.62628 | D14: 37.89322 | E14: 11.721551 | F14: 42.305 | G14: 227.87741 | H14: 149.94489 | I14: 192.27523 | J14: 186.58336 | K14: 123.45557 | L14: 82.081628 | M14: 30.5225 | N14: =Chart!AL3 -> 98.646726 | P14: =AVERAGE(C14:N14) -> 110.57778 | Q14: =+L14/$L$8 -> 0.0098008469
B15: 2 | C15: 169.37109 | D15: 462.87825 | E15: 165.28975 | F15: 70.817693 | G15: 103.91357 | H15: 73.486882 | I15: 113.22533 | J15: 227.57024 | K15: 139.16954 | L15: 80.960977 | M15: 875.70107 | N15: =Chart!AL4 -> 264.99633 | P15: =AVERAGE(C15:N15) -> 228.94839 | Q15: =+L15/$L$8 -> 0.009667037
B16: 3 | C16: 75.336042 | D16: 164.75745 | E16: 213.13334 | F16: 97.985385 | G16: 147.65096 | H16: 135.80742 | I16: 133.03513 | J16: 165.92284 | K16: 317.27697 | L16: 134.05063 | M16: 253.07762 | N16: =Chart!AL5 -> 106.80857 | P16: =AVERAGE(C16:N16) -> 162.0702 | Q16: =+L16/$L$8 -> 0.016006137
B17: 4 | C17: 229.70928 | D17: 125.4329 | E17: 203.14862 | F17: 44.042214 | G17: 130.63982 | H17: 176.91901 | I17: 158.041 | J17: 177.90955 | K17: 115.32461 | L17: 181.20108 | M17: 70.021181 | N17: =Chart!AL6 -> 86.255638 | P17: =AVERAGE(C17:N17) -> 141.55374 | Q17: =+L17/$L$8 -> 0.021636072
B18: 5 | C18: 494.54078 | D18: 132.1901 | E18: 285.56639 | F18: 68.857397 | G18: 105.29555 | H18: 83.625906 | I18: 61.885694 | J18: 225.64807 | K18: 45.198567 | L18: 130.38557 | M18: 510.63905 | N18: =Chart!AL7 -> 171.94257 | P18: =AVERAGE(C18:N18) -> 192.9813 | Q18: =+L18/$L$8 -> 0.015568514
B19: 6 | C19: 328.10568 | D19: 71.182462 | E19: 100.44089 | F19: 137.94512 | G19: 720.47007 | H19: 251.6165 | I19: 143.2332 | J19: 98.578822 | K19: 293.23883 | L19: 93.925685 | M19: 403.61925 | N19: =Chart!AL8 -> 125.08453 | P19: =AVERAGE(C19:N19) -> 230.62009 | Q19: =+L19/$L$8 -> 0.011215071
B20: 7 | C20: 68.281828 | D20: 74.078612 | E20: 233.47343 | F20: 111.09432 | G20: 293.6564 | H20: 212.32241 | I20: 168.20193 | J20: 213.51404 | K20: 208.24556 | L20: 95.786731 | M20: 29.027309 | N20: =Chart!AL9 -> 377.49897 | P20: =AVERAGE(C20:N20) -> 173.76513 | Q20: =+L20/$L$8 -> 0.011437286
B21: 8 | C21: 122.47065 | D21: 218.40905 | E21: 173.96671 | F21: 261.82853 | G21: 20.474391 | H21: 234.51483 | I21: 224.7226 | J21: 18.115296 | K21: 136.53097 | L21: 141.46951 | M21: 324.71876 | N21: =Chart!AL10 -> 141.10319 | P21: =AVERAGE(C21:N21) -> 168.19371 | Q21: =+L21/$L$8 -> 0.016891977
B22: 9 | C22: 219.48585 | D22: 147.1795 | E22: 73.625679 | F22: 310.62813 | G22: 110.73436 | H22: 168.36771 | I22: 439.57604 | J22: 124.83465 | K22: 89.736171 | L22: 489.35197 | M22: 161.91341 | N22: =Chart!AL11 -> 191.81142 | P22: =AVERAGE(C22:N22) -> 210.60374 | Q22: =+L22/$L$8 -> 0.058430417
B23: 10 | C23: 488.12809 | D23: 299.5609 | E23: 238.65937 | F23: 246.99591 | G23: 363.11715 | H23: 172.47405 | I23: 128.86478 | J23: 116.22308 | K23: 89.40627 | L23: 69.200054 | M23: 194.53781 | N23: =Chart!AL12 -> 421.21817 | P23: =AVERAGE(C23:N23) -> 235.6988 | Q23: =+L23/$L$8 -> 0.0082627398
B24: 11 | C24: 319.33303 | D24: 385.3449 | E24: 117.87584 | F24: 124.99828 | G24: 278.35066 | H24: 78.270974 | I24: 176.17555 | J24: 184.01333 | K24: 42.451305 | L24: 164.35133 | M24: 192.24074 | N24: =Chart!AL13 -> 250.42226 | P24: =AVERAGE(C24:N24) -> 192.81902 | Q24: =+L24/$L$8 -> 0.01962415
B25: 12 | C25: 85.124723 | D25: 133.23492 | E25: 316.72132 | F25: 332.41237 | G25: 285.07476 | H25: 199.46537 | I25: 277.10198 | J25: 818.91868 | K25: 155.33819 | L25: 214.61421 | M25: 292.88761 | N25: =Chart!AL14 -> 29.928774 | P25: =AVERAGE(C25:N25) -> 261.73524 | Q25: =+L25/$L$8 -> 0.025625722
... B30: 17 | C30: 149.29672 | D30: 621.2726 | E30: 374.84274 | F30: 430.45997 | G30: 128.68476 | H30: 109.56266 | I30: 218.94094 | J30: 171.20749 | K30: 219.46408 | L30: 557.05144 | M30: 504.91166 | N30: =Chart!AL19 -> 153.45695 | P30: =AVERAGE(C30:N30) -> 303.26267 | Q30: =+L30/$L$8 -> 0.066513981
B31: 18 | C31: 185.57405 | D31: 98.037734 | E31: 315.77789 | F31: 310.13447 | G31: 157.08308 | H31: 431.97303 | I31: 304.45444 | J31: 293.59698 | K31: 199.41614 | L31: 62.533681 | M31: 276.89674 | N31: =Chart!AL20 -> 120.93973 | P31: =AVERAGE(C31:M31) -> 239.58893 | Q31: =+L31/$L$8 -> 0.0074667504 | R31: 1
B32: 19 | C32: 506.2193 | D32: 14.859642 | E32: 148.87717 | F32: 314.29511 | G32: 95.025124 | H32: 110.28142 | I32: 654.44686 | J32: 164.91883 | K32: 109.74645 | L32: 194.36308 | M32: 194.17899 | N32: =Chart!AL21 -> 478.24212 | P32: =AVERAGE(C32:M32) -> 227.92836 | Q32: =+L32/$L$8 -> 0.023207664 | R32: 2
B33: 20 | C33: 116.70328 | D33: 443.16062 | E33: 471.69628 | F33: 167.46663 | G33: 185.25446 | H33: 322.08529 | I33: 228.24349 | J33: 51.025211 | K33: 221.88835 | L33: 347.01656 | M33: 138.12433 | N33: =Chart!AL22 -> 104.99978 | P33: =AVERAGE(C33:M33) -> 244.78768 | Q33: =+L33/$L$8 -> 0.041435047 | R33: 3
B34: 21 | C34: 292.10716 | D34: 257.59192 | E34: 390.62912 | F34: 178.509 | G34: 166.65788 | H34: 423.33213 | I34: 339.81229 | J34: 190.19046 | K34: 408.10523 | L34: 303.45136 | M34: 294.82277 | N34: =Chart!AL23 -> 128.72252 | P34: =AVERAGE(C34:M34) -> 295.01903 | Q34: =+L34/$L$8 -> 0.036233203 | R34: 4
B35: 22 | C35: 261.60632 | D35: -16.341382 | E35: 556.96971 | F35: 218.22986 | G35: 534.7884 | H35: 304.93927 | I35: 253.99575 | J35: 122.97687 | K35: 184.66883 | L35: 336.14278 | M35: 113.72088 | N35: =Chart!AL24 -> 133.89414 | P35: =AVERAGE(C35:M35) -> 261.06339 | Q35: =+L35/$L$8 -> 0.040136678 | R35: 5
B36: 23 | C36: 1364.6611 | D36: 288.9474 | E36: 566.3313 | F36: 114.1409 | G36: 806.17003 | H36: 1560.4675 | I36: 87.457198 | J36: 158.53183 | K36: 57.292928 | L36: 439.42289 | M36: 527.64694 | N36: =Chart!AL25 -> 132.38512 | P36: =AVERAGE(C36:M36) -> 542.82454 | Q36: =+L36/$L$8 -> 0.052468701 | R36: 6
B37: 24 | D37: 1624.3667 | E37: 0.65 | F37: 1416.7411 | G37: 1163.0151 | I37: 161.49684 | J37: 628.42443 | K37: 979.85559 | L37: 287.72435 | M37: 134.39704 | N37: =Chart!AL26 -> 172.12056 | P37: =AVERAGE(C37:M37) -> 710.74123 | Q37: =+L37/$L$8 -> 0.03435534 | R37: 7
B38: 25 | I38: 243.87378 | J38: 323.26383 | K38: 1939.591 | L38: 576.7043 | M38: 717.1466 | N38: =Chart!AL27 -> 518.22255 | P38: =AVERAGE(C38:M38) -> 760.1159 | Q38: =+L38/$L$8 -> 0.068860604 | R38: 8
B39: 26 | I39: 145.97661 | J39: 1427.9589 | L39: 99.571832 | M39: 2114.4219 | P39: =AVERAGE(C39:M39) -> 946.98231 | Q39: =+L39/$L$8 -> 0.011889241 | R39: 9
B40: 27 | I40: 2067.7499 | L40: 2483.8443 | R40: 10
B43: 1.2-4 | C43: Monthly Closing Estimation (M + 1) : Weekly basis
C44: a) Definition | E44: : | F44: Based on daily sales amount, calculate the monthly closing estimation
C45: b) Formula | E45: : | F45: Trend(average daily sales amount, actual working day,remain working day) | S45: (in Million IDR)
F46: Day | G46: Jan | H46: Feb | I46: Mar | J46: Apr | K46: May | L46: Jun | M46: Jul | N46: Aug | O46: Sep | P46: Oct | Q46: Nov | R46: Dec | S46: Total
F47: 1 | G47: =Chart!E3 -> 143.62628 | H47: =Chart!H3 -> 37.89322 | I47: =Chart!K3 -> 11.721551 | J47: =Chart!N3 -> 42.305 | K47: =Chart!Q3 -> 227.87741 | L47: =Chart!T3 -> 149.94489 | M47: =Chart!W3 -> 192.27523 | N47: =Chart!Z3 -> 186.58336 | O47: =Chart!AC3 -> 123.45557 | P47: =Chart!AF3 -> 82.081628 | Q47: =+M14 -> 30.5225 | R47: =Chart!AL3 -> 98.646726 | S47: =SUM(G47:R47) -> 1326.9334
F48: 2 | G48: =Chart!E4 -> 169.37109 | H48: =Chart!H4 -> 462.87825 | I48: =Chart!K4 -> 165.28975 | J48: =Chart!N4 -> 70.817693 | K48: =Chart!Q4 -> 103.91357 | L48: =Chart!T4 -> 73.486882 | M48: =Chart!W4 -> 113.22533 | N48: =Chart!Z4 -> 227.57024 | O48: =Chart!AC4 -> 139.16954 | P48: =Chart!AF4 -> 80.960977 | Q48: =+M15 -> 875.70107 | R48: =Chart!AL4 -> 264.99633 | S48: =SUM(G48:R48) -> 2747.3807
F49: 3 | G49: =Chart!E5 -> 75.336042 | H49: =Chart!H5 -> 164.75745 | I49: =Chart!K5 -> 213.13334 | J49: =Chart!N5 -> 97.985385 | K49: =Chart!Q5 -> 147.65096 | L49: =Chart!T5 -> 135.80742 | M49: =Chart!W5 -> 133.03513 | N49: =Chart!Z5 -> 165.92284 | O49: =Chart!AC5 -> 317.27697 | P49: =Chart!AF5 -> 134.05063 | Q49: =+M16 -> 253.07762 | R49: =Chart!AL5 -> 106.80857 | S49: =SUM(G49:R49) -> 1944.8424
F50: 4 | G50: =Chart!E6 -> 229.70928 | H50: =Chart!H6 -> 125.4329 | I50: =Chart!K6 -> 203.14862 | J50: =Chart!N6 -> 44.042214 | K50: =Chart!Q6 -> 130.63982 | L50: =Chart!T6 -> 176.91901 | M50: =Chart!W6 -> 158.041 | N50: =Chart!Z6 -> 177.90955 | O50: =Chart!AC6 -> 115.32461 | P50: =Chart!AF6 -> 181.20108 | Q50: =+M17 -> 70.021181 | R50: =Chart!AL6 -> 86.255638 | S50: =SUM(G50:R50) -> 1698.6449
F51: 5 | G51: =Chart!E7 -> 494.54078 | H51: =Chart!H7 -> 132.1901 | I51: =Chart!K7 -> 285.56639 | J51: =Chart!N7 -> 68.857397 | K51: =Chart!Q7 -> 105.29555 | L51: =Chart!T7 -> 83.625906 | M51: =Chart!W7 -> 61.885694 | N51: =Chart!Z7 -> 225.64807 | O51: =Chart!AC7 -> 45.198567 | P51: =Chart!AF7 -> 130.38557 | Q51: =+M18 -> 510.63905 | R51: =Chart!AL7 -> 171.94257 | S51: =SUM(G51:R51) -> 2315.7756
F52: 6 | G52: =Chart!E8 -> 328.10568 | H52: =Chart!H8 -> 71.182462 | I52: =Chart!K8 -> 100.44089 | J52: =Chart!N8 -> 137.94512 | K52: =Chart!Q8 -> 720.47007 | L52: =Chart!T8 -> 251.6165 | M52: =Chart!W8 -> 143.2332 | N52: =Chart!Z8 -> 98.578822 | O52: =Chart!AC8 -> 293.23883 | P52: =Chart!AF8 -> 93.925685 | Q52: =+M19 -> 403.61925 | R52: =Chart!AL8 -> 125.08453 | S52: =SUM(G52:R52) -> 2767.441
...

Sheet Chart
C1: January | F1: February | I1: March | L1: April | O1: May | R1: June | U1: July | X1: August | AA1: September | AD1: October | AG1: November | AJ1: December
B2: WD | C2: Target | D2: Acc Jan | E2: Sales | F2: Target | G2: Acc Feb | H2: Sales | I2: Target | J2: Acc Mar | K2: Sales | L2: Target | M2: Acc Apr | N2: Sales | O2: Target | P2: Acc May | Q2: Sales | R2: Target | S2: Acc Jun | T2: Sales | U2: Target | V2: Acc Jul | W2: Sales | X2: Target | Y2: Acc Aug | Z2: Sales | AA2: Target | AB2: Acc Sep | AC2: Sales | AD2: Target | AE2: Acc Oct | AF2: Sales | AG2: Target | AH2: Acc Nov | AI2: Sales | AJ2: Target | AK2: Acc Dec | AL2: Sales | AN2: {=_xlfn.IFS('Daily Sales Performance'!P3="January",C2:E25,'Daily Sales Performance'!P3="February",F2:H26,'Daily Sales Performance'!P3="March",I2:K26,'Daily Sales Performance'!P3="April",L2:N26,'Daily Sales Performance'!P3="May",O2:Q26,'Daily Sales Performance'!P3="June",R2:T25,'Daily Sales Performance'!P3="July",U2:W29,'Daily Sales Performance'!P3="August",X2:Z28,'Daily Sales Performance'!P3="September",AA2:AC27,'Daily Sales Performance'!P3="October",AD2:AF29,'Daily Sales Performance'!P3="November",AG2:AI29,'Daily Sales Performance'!P3="December",AJ2:AL29)} -> Target | AO2: Acc Dec | AP2: Sales
B3: 1 | C3: =Apendix!$C$8 -> 5840.8361 | D3: =E3 -> 143.62628 | E3: 143.62628 | F3: =Apendix!$D$8 -> 6384.4032 | G3: =H3 -> 37.89322 | H3: 37.89322 | I3: =Apendix!$E$8 -> 6581.2264 | J3: =K3 -> 11.721551 | K3: 11.721551 | L3: =Apendix!$F$8 -> 6839.8032 | M3: =N3 -> 42.305 | N3: 42.305 | O3: =Apendix!$G$8 -> 6597.9355 | P3: =Q3 -> 227.87741 | Q3: 227.87741 | R3: =Apendix!$H$8 -> 6706.5427 | S3: =T3 -> 149.94489 | T3: 149.94489 | U3: =Apendix!$I$8 -> 7295.3604 | V3: =W3 -> 192.27523 | W3: 192.27523 | X3: =Apendix!$J$8 -> 7569.093 | Y3: =Z3 -> 186.58336 | Z3: 186.58336 | AA3: =Apendix!$K$8 -> 7763.1358 | AB3: =AC3 -> 123.45557 | AC3: 123.45557 | AD3: =Apendix!$L$8 -> 8374.9526 | AE3: =AF3 -> 82.081628 | AF3: 82.081628 | AG3: =Apendix!$M$8 -> 8441.1287 | AH3: =AI3 -> 30.5225 | AI3: =Apendix!M14 -> 30.5225 | AJ3: =Apendix!$N$8 -> 6605.5799 | AK3: =AL3 -> 98.646726 | AL3: 98.646726 | AN3: 6605.5799 | AO3: 98.646726 | AP3: 98.646726
B4: 2 | C4: =Apendix!$C$8 -> 5840.8361 | D4: =D3+E4 -> 312.99737 | E4: 169.37109 | F4: =Apendix!$D$8 -> 6384.4032 | G4: =G3+H4 -> 500.77147 | H4: 462.87825 | I4: =Apendix!$E$8 -> 6581.2264 | J4: =J3+K4 -> 177.0113 | K4: 165.28975 | L4: =Apendix!$F$8 -> 6839.8032 | M4: =M3+N4 -> 113.12269 | N4: 70.817693 | O4: =Apendix!$G$8 -> 6597.9355 | P4: =P3+Q4 -> 331.79098 | Q4: 103.91357 | R4: =Apendix!$H$8 -> 6706.5427 | S4: =S3+T4 -> 223.43177 | T4: 73.486882 | U4: =Apendix!$I$8 -> 7295.3604 | V4: =V3+W4 -> 305.50056 | W4: 113.22533 | X4: =Apendix!$J$8 -> 7569.093 | Y4: =Y3+Z4 -> 414.15361 | Z4: 227.57024 | AA4: =Apendix!$K$8 -> 7763.1358 | AB4: =AB3+AC4 -> 262.6251 | AC4: 139.16954 | AD4: =Apendix!$L$8 -> 8374.9526 | AE4: =AE3+AF4 -> 163.0426 | AF4: 80.960977 | AG4: =Apendix!$M$8 -> 8441.1287 | AH4: =AH3+AI4 -> 906.22357 | AI4: =Apendix!M15 -> 875.70107 | AJ4: =Apendix!$N$8 -> 6605.5799 | AK4: =AK3+AL4 -> 363.64306 | AL4: 264.99633 | AN4: 6605.5799 | AO4: 363.64306 | AP4: 264.99633
B5: 3 | C5: =Apendix!$C$8 -> 5840.8361 | D5: =D4+E5 -> 388.33342 | E5: 75.336042 | F5: =Apendix!$D$8 -> 6384.4032 | G5: =G4+H5 -> 665.52891 | H5: 164.75745 | I5: =Apendix!$E$8 -> 6581.2264 | J5: =J4+K5 -> 390.14464 | K5: 213.13334 | L5: =Apendix!$F$8 -> 6839.8032 | M5: =M4+N5 -> 211.10808 | N5: 97.985385 | O5: =Apendix!$G$8 -> 6597.9355 | P5: =P4+Q5 -> 479.44194 | Q5: 147.65096 | R5: =Apendix!$H$8 -> 6706.5427 | S5: =S4+T5 -> 359.2392 | T5: 135.80742 | U5: =Apendix!$I$8 -> 7295.3604 | V5: =V4+W5 -> 438.5357 | W5: 133.03513 | X5: =Apendix!$J$8 -> 7569.093 | Y5: =Y4+Z5 -> 580.07644 | Z5: 165.92284 | AA5: =Apendix!$K$8 -> 7763.1358 | AB5: =AB4+AC5 -> 579.90207 | AC5: 317.27697 | AD5: =Apendix!$L$8 -> 8374.9526 | AE5: =AE4+AF5 -> 297.09324 | AF5: 134.05063 | AG5: =Apendix!$M$8 -> 8441.1287 | AH5: =AH4+AI5 -> 1159.3012 | AI5: =Apendix!M16 -> 253.07762 | AJ5: =Apendix!$N$8 -> 6605.5799 | AK5: =AK4+AL5 -> 470.45162 | AL5: 106.80857 | AN5: 6605.5799 | AO5: 470.45162 | AP5: 106.80857
B6: 4 | C6: =Apendix!$C$8 -> 5840.8361 | D6: =D5+E6 -> 618.0427 | E6: 229.70928 | F6: =Apendix!$D$8 -> 6384.4032 | G6: =G5+H6 -> 790.96182 | H6: 125.4329 | I6: =Apendix!$E$8 -> 6581.2264 | J6: =J5+K6 -> 593.29326 | K6: 203.14862 | L6: =Apendix!$F$8 -> 6839.8032 | M6: =M5+N6 -> 255.15029 | N6: 44.042214 | O6: =Apendix!$G$8 -> 6597.9355 | P6: =P5+Q6 -> 610.08176 | Q6: 130.63982 | R6: =Apendix!$H$8 -> 6706.5427 | S6: =S5+T6 -> 536.15821 | T6: 176.91901 | U6: =Apendix!$I$8 -> 7295.3604 | V6: =V5+W6 -> 596.57669 | W6: 158.041 | X6: =Apendix!$J$8 -> 7569.093 | Y6: =Y5+Z6 -> 757.986 | Z6: 177.90955 | AA6: =Apendix!$K$8 -> 7763.1358 | AB6: =AB5+AC6 -> 695.22668 | AC6: 115.32461 | AD6: =Apendix!$L$8 -> 8374.9526 | AE6: =AE5+AF6 -> 478.29432 | AF6: 181.20108 | AG6: =Apendix!$M$8 -> 8441.1287 | AH6: =AH5+AI6 -> 1229.3224 | AI6: =Apendix!M17 -> 70.021181 | AJ6: =Apendix!$N$8 -> 6605.5799 | AK6: =AK5+AL6 -> 556.70726 | AL6: 86.255638 | AN6: 6605.5799 | AO6: 556.70726 | AP6: 86.255638
B7: 5 | C7: =Apendix!$C$8 -> 5840.8361 | D7: =D6+E7 -> 1112.5835 | E7: 494.54078 | F7: =Apendix!$D$8 -> 6384.4032 | G7: =G6+H7 -> 923.15192 | H7: 132.1901 | I7: =Apendix!$E$8 -> 6581.2264 | J7: =J6+K7 -> 878.85964 | K7: 285.56639 | L7: =Apendix!$F$8 -> 6839.8032 | M7: =M6+N7 -> 324.00769 | N7: 68.857397 | O7: =Apendix!$G$8 -> 6597.9355 | P7: =P6+Q7 -> 715.37731 | Q7: 105.29555 | R7: =Apendix!$H$8 -> 6706.5427 | S7: =S6+T7 -> 619.78411 | T7: 83.625906 | U7: =Apendix!$I$8 -> 7295.3604 | V7: =V6+W7 -> 658.46239 | W7: 61.885694 | X7: =Apendix!$J$8 -> 7569.093 | Y7: =Y6+Z7 -> 983.63407 | Z7: 225.64807 | AA7: =Apendix!$K$8 -> 7763.1358 | AB7: =AB6+AC7 -> 740.42525 | AC7: 45.198567 | AD7: =Apendix!$L$8 -> 8374.9526 | AE7: =AE6+AF7 -> 608.67988 | AF7: 130.38557 | AG7: =Apendix!$M$8 -> 8441.1287 | AH7: =AH6+AI7 -> 1739.9614 | AI7: =Apendix!M18 -> 510.63905 | AJ7: =Apendix!$N$8 -> 6605.5799 | AK7: =AK6+AL7 -> 728.64983 | AL7: 171.94257 | AN7: 6605.5799 | AO7: 728.64983 | AP7: 171.94257
B8: 6 | C8: =Apendix!$C$8 -> 5840.8361 | D8: =D7+E8 -> 1440.6891 | E8: 328.10568 | F8: =Apendix!$D$8 -> 6384.4032 | G8: =G7+H8 -> 994.33438 | H8: 71.182462 | I8: =Apendix!$E$8 -> 6581.2264 | J8: =J7+K8 -> 979.30054 | K8: 100.44089 | L8: =Apendix!$F$8 -> 6839.8032 | M8: =M7+N8 -> 461.95281 | N8: 137.94512 | O8: =Apendix!$G$8 -> 6597.9355 | P8: =P7+Q8 -> 1435.8474 | Q8: 720.47007 | R8: =Apendix!$H$8 -> 6706.5427 | S8: =S7+T8 -> 871.40061 | T8: 251.6165 | U8: =Apendix!$I$8 -> 7295.3604 | V8: =V7+W8 -> 801.69559 | W8: 143.2332 | X8: =Apendix!$J$8 -> 7569.093 | Y8: =Y7+Z8 -> 1082.2129 | Z8: 98.578822 | AA8: =Apendix!$K$8 -> 7763.1358 | AB8: =AB7+AC8 -> 1033.6641 | AC8: 293.23883 | AD8: =Apendix!$L$8 -> 8374.9526 | AE8: =AE7+AF8 -> 702.60557 | AF8: 93.925685 | AG8: =Apendix!$M$8 -> 8441.1287 | AH8: =AH7+AI8 -> 2143.5807 | AI8: =Apendix!M19 -> 403.61925 | AJ8: =Apendix!$N$8 -> 6605.5799 | AK8: =AK7+AL8 -> 853.73436 | AL8: 125.08453 | AN8: 6605.5799 | AO8: 853.73436 | AP8: 125.08453
B9: 7 | C9: =Apendix!$C$8 -> 5840.8361 | D9: =D8+E9 -> 1508.971 | E9: 68.281828 | F9: =Apendix!$D$8 -> 6384.4032 | G9: =G8+H9 -> 1068.413 | H9: 74.078612 | I9: =Apendix!$E$8 -> 6581.2264 | J9: =J8+K9 -> 1212.774 | K9: 233.47343 | L9: =Apendix!$F$8 -> 6839.8032 | M9: =M8+N9 -> 573.04713 | N9: 111.09432 | O9: =Apendix!$G$8 -> 6597.9355 | P9: =P8+Q9 -> 1729.5038 | Q9: 293.6564 | R9: =Apendix!$H$8 -> 6706.5427 | S9: =S8+T9 -> 1083.723 | T9: 212.32241 | U9: =Apendix!$I$8 -> 7295.3604 | V9: =V8+W9 -> 969.89753 | W9: 168.20193 | X9: =Apendix!$J$8 -> 7569.093 | Y9: =Y8+Z9 -> 1295.7269 | Z9: 213.51404 | AA9: =Apendix!$K$8 -> 7763.1358 | AB9: =AB8+AC9 -> 1241.9096 | AC9: 208.24556 | AD9: =Apendix!$L$8 -> 8374.9526 | AE9: =AE8+AF9 -> 798.3923 | AF9: 95.786731 | AG9: =Apendix!$M$8 -> 8441.1287 | AH9: =AH8+AI9 -> 2172.608 | AI9: =Apendix!M20 -> 29.027309 | AJ9: =Apendix!$N$8 -> 6605.5799 | AK9: =AK8+AL9 -> 1231.2333 | AL9: 377.49897 | AN9: 6605.5799 | AO9: 1231.2333 | AP9: 377.49897
B10: 8 | C10: =Apendix!$C$8 -> 5840.8361 | D10: =D9+E10 -> 1631.4416 | E10: 122.47065 | F10: =Apendix!$D$8 -> 6384.4032 | G10: =G9+H10 -> 1286.822 | H10: 218.40905 | I10: =Apendix!$E$8 -> 6581.2264 | J10: =J9+K10 -> 1386.7407 | K10: 173.96671 | L10: =Apendix!$F$8 -> 6839.8032 | M10: =M9+N10 -> 834.87566 | N10: 261.82853 | O10: =Apendix!$G$8 -> 6597.9355 | P10: =P9+Q10 -> 1749.9782 | Q10: 20.474391 | R10: =Apendix!$H$8 -> 6706.5427 | S10: =S9+T10 -> 1318.2378 | T10: 234.51483 | U10: =Apendix!$I$8 -> 7295.3604 | V10: =V9+W10 -> 1194.6201 | W10: 224.7226 | X10: =Apendix!$J$8 -> 7569.093 | Y10: =Y9+Z10 -> 1313.8422 | Z10: 18.115296 | AA10: =Apendix!$K$8 -> 7763.1358 | AB10: =AB9+AC10 -> 1378.4406 | AC10: 136.53097 | AD10: =Apendix!$L$8 -> 8374.9526 | AE10: =AE9+AF10 -> 939.86181 | AF10: 141.46951 | AG10: =Apendix!$M$8 -> 8441.1287 | AH10: =AH9+AI10 -> 2497.3267 | AI10: =Apendix!M21 -> 324.71876 | AJ10: =Apendix!$N$8 -> 6605.5799 | AK10: =AK9+AL10 -> 1372.3365 | AL10: 141.10319 | AN10: 6605.5799 | AO10: 1372.3365 | AP10: 141.10319
B11: 9 | C11: =Apendix!$C$8 -> 5840.8361 | D11: =D10+E11 -> 1850.9275 | E11: 219.48585 | F11: =Apendix!$D$8 -> 6384.4032 | G11: =G10+H11 -> 1434.0015 | H11: 147.1795 | I11: =Apendix!$E$8 -> 6581.2264 | J11: =J10+K11 -> 1460.3664 | K11: 73.625679 | L11: =Apendix!$F$8 -> 6839.8032 | M11: =M10+N11 -> 1145.5038 | N11: 310.62813 | O11: =Apendix!$G$8 -> 6597.9355 | P11: =P10+Q11 -> 1860.7125 | Q11: 110.73436 | R11: =Apendix!$H$8 -> 6706.5427 | S11: =S10+T11 -> 1486.6056 | T11: 168.36771 | U11: =Apendix!$I$8 -> 7295.3604 | V11: =V10+W11 -> 1634.1962 | W11: 439.57604 | X11: =Apendix!$J$8 -> 7569.093 | Y11: =Y10+Z11 -> 1438.6769 | Z11: 124.83465 | AA11: =Apendix!$K$8 -> 7763.1358 | AB11: =AB10+AC11 -> 1468.1768 | AC11: 89.736171 | AD11: =Apendix!$L$8 -> 8374.9526 | AE11: =AE10+AF11 -> 1429.2138 | AF11: 489.35197 | AG11: =Apendix!$M$8 -> 8441.1287 | AH11: =AH10+AI11 -> 2659.2401 | AI11: =Apendix!M22 -> 161.91341 | AJ11: =Apendix!$N$8 -> 6605.5799 | AK11: =AK10+AL11 -> 1564.1479 | AL11: 191.81142 | AN11: 6605.5799 | AO11: 1564.1479 | AP11: 191.81142
B12: 10 | C12: =Apendix!$C$8 -> 5840.8361 | D12: =D11+E12 -> 2339.0556 | E12: 488.12809 | F12: =Apendix!$D$8 -> 6384.4032 | G12: =G11+H12 -> 1733.5624 | H12: 299.5609 | I12: =Apendix!$E$8 -> 6581.2264 | J12: =J11+K12 -> 1699.0257 | K12: 238.65937 | L12: =Apendix!$F$8 -> 6839.8032 | M12: =M11+N12 -> 1392.4997 | N12: 246.99591 | O12: =Apendix!$G$8 -> 6597.9355 | P12: =P11+Q12 -> 2223.8297 | Q12: 363.11715 | R12: =Apendix!$H$8 -> 6706.5427 | S12: =S11+T12 -> 1659.0796 | T12: 172.47405 | U12: =Apendix!$I$8 -> 7295.3604 | V12: =V11+W12 -> 1763.0609 | W12: 128.86478 | X12: =Apendix!$J$8 -> 7569.093 | Y12: =Y11+Z12 -> 1554.9 | Z12: 116.22308 | AA12: =Apendix!$K$8 -> 7763.1358 | AB12: =AB11+AC12 -> 1557.5831 | AC12: 89.40627 | AD12: =Apendix!$L$8 -> 8374.9526 | AE12: =AE11+AF12 -> 1498.4138 | AF12: 69.200054 | AG12: =Apendix!$M$8 -> 8441.1287 | AH12: =AH11+AI12 -> 2853.778 | AI12: =Apendix!M23 -> 194.53781 | AJ12: =Apendix!$N$8 -> 6605.5799 | AK12: =AK11+AL12 -> 1985.3661 | AL12: 421.21817 | AN12: 6605.5799 | AO12: 1985.3661 | AP12: 421.21817
B13: 11 | C13: =Apendix!$C$8 -> 5840.8361 | D13: =D12+E13 -> 2658.3886 | E13: 319.33303 | F13: =Apendix!$D$8 -> 6384.4032 | G13: =G12+H13 -> 2118.9073 | H13: 385.3449 | I13: =Apendix!$E$8 -> 6581.2264 | J13: =J12+K13 -> 1816.9016 | K13: 117.87584 | L13: =Apendix!$F$8 -> 6839.8032 | M13: =M12+N13 -> 1517.498 | N13: 124.99828 | O13: =Apendix!$G$8 -> 6597.9355 | P13: =P12+Q13 -> 2502.1803 | Q13: 278.35066 | R13: =Apendix!$H$8 -> 6706.5427 | S13: =S12+T13 -> 1737.3506 | T13: 78.270974 | U13: =Apendix!$I$8 -> 7295.3604 | V13: =V12+W13 -> 1939.2365 | W13: 176.17555 | X13: =Apendix!$J$8 -> 7569.093 | Y13: =Y12+Z13 -> 1738.9133 | Z13: 184.01333 | AA13: =Apendix!$K$8 -> 7763.1358 | AB13: =AB12+AC13 -> 1600.0344 | AC13: 42.451305 | AD13: =Apendix!$L$8 -> 8374.9526 | AE13: =AE12+AF13 -> 1662.7652 | AF13: 164.35133 | AG13: =Apendix!$M$8 -> 8441.1287 | AH13: =AH12+AI13 -> 3046.0187 | AI13: =Apendix!M24 -> 192.24074 | AJ13: =Apendix!$N$8 -> 6605.5799 | AK13: =AK12+AL13 -> 2235.7884 | AL13: 250.42226 | AN13: 6605.5799 | AO13: 2235.7884 | AP13: 250.42226
B14: 12 | C14: =Apendix!$C$8 -> 5840.8361 | D14: =D13+E14 -> 2743.5133 | E14: 85.124723 | F14: =Apendix!$D$8 -> 6384.4032 | G14: =G13+H14 -> 2252.1423 | H14: 133.23492 | I14: =Apendix!$E$8 -> 6581.2264 | J14: =J13+K14 -> 2133.6229 | K14: 316.72132 | L14: =Apendix!$F$8 -> 6839.8032 | M14: =M13+N14 -> 1849.9104 | N14: 332.41237 | O14: =Apendix!$G$8 -> 6597.9355 | P14: =P13+Q14 -> 2787.2551 | Q14: 285.07476 | R14: =Apendix!$H$8 -> 6706.5427 | S14: =S13+T14 -> 1936.816 | T14: 199.46537 | U14: =Apendix!$I$8 -> 7295.3604 | V14: =V13+W14 -> 2216.3385 | W14: 277.10198 | X14: =Apendix!$J$8 -> 7569.093 | Y14: =Y13+Z14 -> 2557.832 | Z14: 818.91868 | AA14: =Apendix!$K$8 -> 7763.1358 | AB14: =AB13+AC14 -> 1755.3725 | AC14: 155.33819 | AD14: =Apendix!$L$8 -> 8374.9526 | AE14: =AE13+AF14 -> 1877.3794 | AF14: 214.61421 | AG14: =Apendix!$M$8 -> 8441.1287 | AH14: =AH13+AI14 -> 3338.9063 | AI14: =Apendix!M25 -> 292.88761 | AJ14: =Apendix!$N$8 -> 6605.5799 | AK14: =AK13+AL14 -> 2265.7171 | AL14: 29.928774 | AN14: 6605.5799 | AO14: 2265.7171 | AP14: 29.928774
B15: 13 | C15: =Apendix!$C$8 -> 5840.8361 | D15: =D14+E15 -> 3158.098 | E15: 414.58466 | F15: =Apendix!$D$8 -> 6384.4032 | G15: =G14+H15 -> 2327.9281 | H15: 75.785885 | I15: =Apendix!$E$8 -> 6581.2264 | J15: =J14+K15 -> 2208.9092 | K15: 75.28634 | L15: =Apendix!$F$8 -> 6839.8032 | M15: =M14+N15 -> 2078.6358 | N15: 228.72549 | O15: =Apendix!$G$8 -> 6597.9355 | P15: =P14+Q15 -> 2832.8467 | Q15: 45.591582 | R15: =Apendix!$H$8 -> 6706.5427 | S15: =S14+T15 -> 2104.3572 | T15: 167.5412 | U15: =Apendix!$I$8 -> 7295.3604 | V15: =V14+W15 -> 2323.4131 | W15: 107.07464 | X15: =Apendix!$J$8 -> 7569.093 | Y15: =Y14+Z15 -> 2721.5349 | Z15: 163.70291 | AA15: =Apendix!$K$8 -> 7763.1358 | AB15: =AB14+AC15 -> 1849.1858 | AC15: 93.813269 | AD15: =Apendix!$L$8 -> 8374.9526 | AE15: =AE14+AF15 -> 2024.424 | AF15: 147.0446 | AG15: =Apendix!$M$8 -> 8441.1287 | AH15: =AH14+AI15 -> 3631.7939 | AI15: =Apendix!M26 -> 292.88761 | AJ15: =Apendix!$N$8 -> 6605.5799 | AK15: =AK14+AL15 -> 2603.5622 | AL15: 337.84508 | AN15: 6605.5799 | AO15: 2603.5622 | AP15: 337.84508
... B25: 23 | C25: =Apendix!$C$8 -> 5840.8361 | D25: =D24+E25 -> 7165.1067 | E25: 1364.6611 | F25: =Apendix!$D$8 -> 6384.4032 | G25: =G24+H25 -> 4448.0709 | H25: 288.9474 | I25: =Apendix!$E$8 -> 6581.2264 | J25: =J24+K25 -> 6047.0687 | K25: 566.3313 | L25: =Apendix!$F$8 -> 6839.8032 | M25: =M24+N25 -> 4460.503 | N25: 114.1409 | O25: =Apendix!$G$8 -> 6597.9355 | P25: =P24+Q25 -> 5582.9711 | Q25: 806.17003 | R25: =Apendix!$H$8 -> 6706.5427 | S25: =S24+T25 -> 6104.9563 | T25: 1560.4675 | U25: =Apendix!$I$8 -> 7295.3604 | V25: =V24+W25 -> 5277.9807 | W25: 87.457198 | X25: =Apendix!$J$8 -> 7569.093 | Y25: =Y24+Z25 -> 4265.5293 | Z25: 158.53183 | AA25: =Apendix!$K$8 -> 7763.1358 | AB25: =AB24+AC25 -> 3944.7085 | AC25: 57.292928 | AD25: =Apendix!$L$8 -> 8374.9526 | AE25: =AE24+AF25 -> 4787.9013 | AF25: 439.42289 | AG25: =Apendix!$M$8 -> 8441.1287 | AH25: =AH24+AI25 -> 6481.5669 | AI25: =Apendix!M36 -> 527.64694 | AJ25: =Apendix!$N$8 -> 6605.5799 | AK25: =AK24+AL25 -> 4657.439 | AL25: 132.38512 | AN25: 6605.5799 | AO25: 4657.439 | AP25: 132.38512
B26: 24 | F26: =Apendix!$D$8 -> 6384.4032 | G26: =G25+H26 -> 6072.4376 | H26: 1624.3667 | I26: =Apendix!$E$8 -> 6581.2264 | J26: =J25+K26 -> 6047.7187 | K26: 0.65 | L26: =Apendix!$F$8 -> 6839.8032 | M26: =M25+N26 -> 5877.2441 | N26: 1416.7411 | O26: =Apendix!$G$8 -> 6597.9355 | P26: =P25+Q26 -> 6745.9862 | Q26: 1163.0151 | U26: =Apendix!$I$8 -> 7295.3604 | V26: =V25+W26 -> 5439.4775 | W26: 161.49684 | X26: =Apendix!$J$8 -> 7569.093 | Y26: =Y25+Z26 -> 4893.9537 | Z26: 628.42443 | AA26: =Apendix!$K$8 -> 7763.1358 | AB26: =AB25+AC26 -> 4924.5641 | AC26: 979.85559 | AD26: =Apendix!$L$8 -> 8374.9526 | AE26: =AE25+AF26 -> 5075.6256 | AF26: 287.72435 | AH26: =AH25+AI26 -> 6615.9639 | AI26: =Apendix!M37 -> 134.39704 | AJ26: =Apendix!$N$8 -> 6605.5799 | AK26: =AK25+AL26 -> 4829.5596 | AL26: 172.12056 | AN26: 6605.5799 | AO26: 4829.5596 | AP26: 172.12056
B27: 25 | U27: =Apendix!$I$8 -> 7295.3604 | V27: =V26+W27 -> 5683.3513 | W27: 243.87378 | X27: =Apendix!$J$8 -> 7569.093 | Y27: =Y26+Z27 -> 5217.2175 | Z27: 323.26383 | AA27: =Apendix!$K$8 -> 7763.1358 | AB27: =AB26+AC27 -> 6864.155 | AC27: 1939.591 | AD27: =Apendix!$L$8 -> 8374.9526 | AE27: =AE26+AF27 -> 5652.3299 | AF27: 576.7043 | AH27: =AH26+AI27 -> 7333.1105 | AI27: =Apendix!M38 -> 717.1466 | AJ27: =Apendix!$N$8 -> 6605.5799 | AK27: =AK26+AL27 -> 5347.7821 | AL27: 518.22255 | AN27: 6605.5799 | AO27: 5347.7821 | AP27: 518.22255
B28: 26 | U28: =Apendix!$I$8 -> 7295.3604 | V28: =V27+W28 -> 5829.3279 | W28: 145.97661 | X28: =Apendix!$J$8 -> 7569.093 | Y28: =Y27+Z28 -> 6645.1764 | Z28: 1427.9589 | AD28: =Apendix!$L$8 -> 8374.9526 | AE28: =AE27+AF28 -> 5751.9017 | AF28: 99.571832 | AH28: =AH27+AI28 -> 9447.5324 | AI28: =Apendix!M39 -> 2114.4219 | AN28: 0 | AO28: 0 | AP28: 0
B29: 27 | U29: =Apendix!$I$8 -> 7295.3604 | V29: =V28+W29 -> 7897.0778 | W29: 2067.7499 | AD29: =Apendix!$L$8 -> 8374.9526 | AE29: =AE28+AF29 -> 8235.7461 | AF29: 2483.8443 | AI29: =Apendix!M40 -> 0 | AN29: 0 | AO29: 0 | AP29: 0

Sheet Sheet4
C3: January
C4: February
C5: March
C6: April
C7: May
C8: June
C9: July
C10: August
C11: September
C12: October
C13: November
C14: December
